Workbook

Sheet Por pcia
G1: 2026
G2: MES | H2: Nominal | K2: Porcentual
H3: NEUQUÉN | I3: RN | J3: Total | K3: NEUQUÉN | L3: RN | M3: Cotización U$S
G4: 1 | H4: =SUM('2026'!J3:N23) -> 621199538 | I4: =SUM('2026'!B3:I23) -> 528090445 | J4: =SUM(H4:I4) -> 1149289983 | K4: =H4/J4 -> 0.54050722 | L4: =I4/J4 -> 0.45949278 | M4: 1458.88 | N4: =J4/M4 -> 787789.25
G5: 2 | H5: =SUM('2026'!J27:N47) -> 402441103 | I5: =SUM('2026'!B27:I47) -> 484522502 | J5: =SUM(H5:I5) -> 886963605 | K5: =H5/J5 -> 0.45372899 | L5: =I5/J5 -> 0.54627101 | M5: 1441.19 | N5: =J5/M5 -> 615438.36
G6: 3 | H6: =SUM('2026'!J51:N71) -> 357402618 | I6: =SUM('2026'!B51:F71) -> 345293187 | J6: =SUM(H6:I6) -> 702695805 | K6: =H6/J6 -> 0.50861641 | L6: =I6/J6 -> 0.49138359 | M6: 1423.78 | N6: =J6/M6 -> 493542.4
G7: 4 | H7: =SUM('2026'!J75:M95) -> 363503529 | I7: =SUM('2026'!B75:I95) -> 384836491 | J7: =SUM(H7:I7) -> 748340020 | K7: =H7/J7 -> 0.48574648 | L7: =I7/J7 -> 0.51425352 | M7: 1442.43 | N7: =J7/M7 -> 518805.09
G8: 5 | H8: =SUM('2026'!J99:M119) -> 388526644 | I8: =SUM('2026'!B99:I119) -> 580381797 | J8: =SUM(H8:I8) -> 968908441 | K8: =H8/J8 -> 0.40099418 | L8: =I8/J8 -> 0.59900582 | M8: 1438.6 | N8: =J8/M8 -> 673507.88
G9: 6 | H9: =SUM('2026'!J123:N143) -> 535064137 | I9: =SUM('2026'!B123:I143) -> 611194686 | J9: =SUM(H9:I9) -> 1146258823 | K9: =H9/J9 -> 0.46679173 | L9: =I9/J9 -> 0.53320827 | M9: 1521.37 | N9: =J9/M9 -> 753438.56
G10: 7 | H10: =SUM('2026'!J147:N167) -> 70774160 | I10: =SUM('2026'!B147:I167) -> 169174731 | J10: =SUM(H10:I10) -> 239948891 | K10: =H10/J10 -> 0.29495515 | L10: =I10/J10 -> 0.70504485 | N10: =J10/M10 -> #DIV/0!
G11: 8 | K11: =H11/J11 -> #DIV/0! | L11: =I11/J11 -> #DIV/0! | N11: =J11/M11 -> #DIV/0!
G12: 9 | K12: =H12/J12 -> #DIV/0! | L12: =I12/J12 -> #DIV/0! | N12: =J12/M12 -> #DIV/0!
G13: 10 | K13: =H13/J13 -> #DIV/0! | L13: =I13/J13 -> #DIV/0! | N13: =J13/M13 -> #DIV/0!
G14: 11 | K14: =H14/J14 -> #DIV/0! | L14: =I14/J14 -> #DIV/0! | N14: =J14/M14 -> #DIV/0!
G15: 12 | K15: =H15/J15 -> #DIV/0! | L15: =I15/J15 -> #DIV/0! | N15: =J15/M15 -> #DIV/0!
G16: TOTAL ANUAL | H16: =SUM(H4:H14) -> 2738911729 | I16: =SUM(I4:I14) -> 3103493839 | J16: =SUM(H16:I16) -> 5842405568 | K16: =H16/J16 -> 0.46879863 | L16: =I16/J16 -> 0.53120137 | N16: =SUM(N4:N15) -> #DIV/0!
G19: 2025
G20: MES | H20: Nominal | K20: Porcentual
H21: NEUQUÉN | I21: RN | J21: Total | K21: NEUQUÉN | L21: RN
G22: 1 | H22: =SUM('2025'!K2:M22) -> 610603144 | I22: =SUM('2025'!B2:G22) -> 426029122 | J22: =SUM(H22:I22) -> 1036632266 | K22: =H22/J22 -> 0.58902579 | L22: =I22/J22 -> 0.41097421 | M22: 1164.89 | N22: =J22/M22 -> 889897.13
G23: 2 | H23: =SUM('2025'!J26:N46) -> 2.5600693e+08 | I23: =SUM('2025'!B26:G46) -> 4.0459826e+08 | J23: =SUM(H23:I23) -> 6.606052e+08 | K23: =H23/J23 -> 0.38753394 | L23: =I23/J23 -> 0.61246606 | M23: 1228.48 | N23: =J23/M23 -> 537741.92
G24: 3 | H24: =SUM('2025'!J50:N70) -> 2.8904159e+08 | I24: =SUM('2025'!B50:F70) -> 2.3067664e+08 | J24: =SUM(H24:I24) -> 5.1971823e+08 | K24: =H24/J24 -> 0.55615058 | L24: =I24/J24 -> 0.44384942 | M24: 1313.97 | N24: =J24/M24 -> 395532.8
G25: 4 | H25: =SUM('2025'!J74:N94) -> 311091570 | I25: =SUM('2025'!B74:G94) -> 322131725 | J25: =SUM(H25:I25) -> 633223295 | K25: =H25/J25 -> 0.49128257 | L25: =I25/J25 -> 0.50871743 | M25: 1183.37 | N25: =J25/M25 -> 535101.7
G26: 5 | H26: =SUM('2025'!J98:N118) -> 412393753 | I26: =SUM('2025'!B98:H118) -> 391409304 | J26: =SUM(H26:I26) -> 803803057 | K26: =H26/J26 -> 0.51305323 | L26: =I26/J26 -> 0.48694677 | M26: 1191.72 | N26: =J26/M26 -> 674489.86
G27: 6 | H27: =SUM('2025'!J122:N142) -> 412176563 | I27: =SUM('2025'!B122:G142) -> 337774396 | J27: =SUM(H27:I27) -> 749950959 | K27: =H27/J27 -> 0.54960469 | L27: =I27/J27 -> 0.45039531 | M27: 1211.1 | N27: =J27/M27 -> 619231.24
G28: 7 | H28: =SUM('2025'!J146:N166) -> 431986337 | I28: =SUM('2025'!B146:H166) -> 473997945 | J28: =SUM(H28:I28) -> 905984282 | K28: =H28/J28 -> 0.47681438 | L28: =I28/J28 -> 0.52318562 | M28: 1359.76 | N28: =J28/M28 -> 666282.49
G29: 8 | H29: =SUM('2025'!J170:N190) -> 431052237 | I29: =SUM('2025'!B170:H190) -> 1204135150 | J29: =SUM(H29:I29) -> 1635187387 | K29: =H29/J29 -> 0.2636103 | L29: =I29/J29 -> 0.7363897 | M29: 1357.34 | N29: =J29/M29 -> 1204699.9
G30: 9 | H30: =SUM('2025'!J194:M214) -> 382875824 | I30: =SUM('2025'!B194:G214) -> 415589717 | J30: =SUM(H30:I30) -> 798465541 | K30: =H30/J30 -> 0.47951452 | L30: =I30/J30 -> 0.52048548 | M30: 1494.02 | N30: =J30/M30 -> 534441
G31: 10 | H31: =SUM('2025'!J218:N238) -> 391952349 | I31: =SUM('2025'!B218:I238) -> 690747316 | J31: =SUM(H31:I31) -> 1082699665 | K31: =H31/J31 -> 0.36201392 | L31: =I31/J31 -> 0.63798608 | M31: 1477.46 | N31: =J31/M31 -> 732811.49
G32: 11 | H32: =SUM('2025'!J242:N262) -> 360492074 | I32: =SUM('2025'!B242:I262) -> 849966871 | J32: =SUM(H32:I32) -> 1210458945 | K32: =H32/J32 -> 0.29781437 | L32: =I32/J32 -> 0.70218563 | M32: 1476.42 | N32: =J32/M32 -> 819860.84
G33: 12 | H33: =SUM('2025'!J266:N286) -> 486112985 | I33: =SUM('2025'!B266:I286) -> 579165118 | J33: =SUM(H33:I33) -> 1065278103 | K33: =H33/J33 -> 0.45632496 | L33: =I33/J33 -> 0.54367504 | M33: 1492.01 | N33: =J33/M33 -> 713988.58
G34: TOTAL ANUAL | H34: =SUM(H22:H32) -> 4289672378 | I34: =SUM(I22:I32) -> 5747056444 | J34: =SUM(H34:I34) -> 10036728822 | K34: =H34/J34 -> 0.42739746 | L34: =I34/J34 -> 0.57260254 | N34: =SUM(N22:N33) -> 8324079
G36: 2024
G37: MES | H37: Nominal | K37: Porcentual
H38: NEUQUÉN | I38: RN | J38: Total | K38: NEUQUÉN | L38: RN
G39: 1 | H39: =SUM('2024'!H2:L19) -> 86019148 | I39: =SUM('2024'!B2:E19) -> 65940618 | J39: =SUM(H39:I39) -> 1.5195977e+08 | K39: =H39/J39 -> 0.56606529 | L39: =I39/J39 -> 0.43393471 | M39: 1175.67 | N39: =J39/M39 -> 129253.76
G40: 2 | H40: =SUM('2024'!H24:K41) -> 1.1316993e+08 | I40: =SUM('2024'!B24:F41) -> 1.063097e+08 | J40: =SUM(H40:I40) -> 2.1947963e+08 | K40: =H40/J40 -> 0.51562842 | L40: =I40/J40 -> 0.48437158 | M40: 1032.24 | N40: =J40/M40 -> 212624.61
G41: 3 | H41: =SUM('2024'!H46:K63) -> 1.8902816e+08 | I41: =SUM('2024'!B46:E63) -> 95678866 | J41: =SUM(H41:I41) -> 2.8470703e+08 | K41: =H41/J41 -> 0.66393922 | L41: =I41/J41 -> 0.33606078 | M41: 1016.09 | N41: =J41/M41 -> 280198.63
G42: 4 | H42: =SUM('2024'!H68:L85) -> 1.7426188e+08 | I42: =SUM('2024'!B68:G85) -> 1.4595913e+08 | J42: =SUM(H42:I42) -> 320221007 | K42: =H42/J42 -> 0.54419252 | L42: =I42/J42 -> 0.45580748 | M42: 1040.89 | N42: =J42/M42 -> 307641.54
G43: 5 | H43: =SUM('2024'!H90:K107) -> 2.0684031e+08 | I43: =SUM('2024'!B90:G107) -> 177839246 | J43: =SUM(H43:I43) -> 3.8467955e+08 | K43: =H43/J43 -> 0.53769509 | L43: =I43/J43 -> 0.46230491 | M43: 1215.93 | N43: =J43/M43 -> 316366.53
...

Sheet 2026
B2: 46030 | C2: 46037 | D2: 46045 | E2: 46046 | F2: 46049 | G2: 46052 | J2: 46027 | K2: 46038 | L2: 46052 | M2: 46049 | O2: Totales
A3: ALVAREZ LUCAS | B3: 2155229 | C3: 4890094 | D3: 14978862 | E3: 2999837 | F3: 69911 | G3: 1471772 | J3: 226723 | K3: 15473393 | L3: 15177338 | M3: 293849 | O3: =SUM(B3:M3) -> 57737008 | P3: =O3/$O$3 -> 1
A4: BURGUEÑO LUCAS | B4: 2155229 | C4: 4890094 | D4: 14978862 | E4: 2999837 | F4: 69911 | G4: 1471772 | J4: 226723 | K4: 15473393 | L4: 15177338 | M4: 293849 | O4: =SUM(B4:M4) -> 57737008 | P4: =O4/$O$3 -> 1
A5: CASTRO | B5: 2155229 | C5: 4890094 | D5: 14978862 | E5: 2999837 | F5: 69911 | G5: 1471772 | J5: 226723 | K5: 15473393 | L5: 15177338 | M5: 293849 | O5: =SUM(B5:M5) -> 57737008 | P5: =O5/$O$3 -> 1
A6: CONSIGLI ROBERTO CARLOS | B6: 2155229 | C6: 4890094 | D6: 14978862 | E6: 2999837 | F6: 69911 | G6: 1471772 | J6: 226723 | K6: 15473393 | L6: 15177338 | M6: 293849 | O6: =SUM(B6:M6) -> 57737008 | P6: =O6/$O$3 -> 1
A7: DEGREEF | B7: 2155229 | C7: 4890094 | D7: 14978862 | E7: 2999837 | F7: 69911 | G7: 1471772 | J7: 226723 | K7: 15473393 | L7: 15177338 | M7: 293849 | O7: =SUM(B7:M7) -> 57737008 | P7: =O7/$O$3 -> 1
A8: ESPINOSA | B8: 1539449 | C8: 3492924 | D8: 10699187 | E8: 2142741 | F8: 49936 | G8: 1051266 | J8: 161945 | K8: 11052424 | L8: 10840956 | M8: 209892 | O8: =SUM(B8:M8) -> 41240720 | P8: =O8/$O$3 -> 0.71428571
A9: GARCIA | B9: 2155229 | C9: 4890094 | D9: 14978862 | E9: 2999837 | F9: 69911 | G9: 1471772 | J9: 226723 | K9: 15473393 | L9: 15177338 | M9: 293849 | O9: =SUM(B9:M9) -> 57737008 | P9: =O9/$O$3 -> 1
A10: GIOJA MARIO ERNESTO | B10: 1539449 | C10: 3492924 | D10: 10699187 | E10: 2142741 | F10: 49936 | G10: 1051266 | J10: 161945 | K10: 11052424 | L10: 10840956 | M10: 209892 | O10: =SUM(B10:M10) -> 41240720 | P10: =O10/$O$3 -> 0.71428571
A11: GOGORZA NICOLAS | B11: 2155229 | C11: 4890094 | D11: 14978862 | E11: 2999837 | F11: 69911 | G11: 1471772 | J11: 226723 | K11: 15473393 | L11: 15177338 | M11: 293849 | O11: =SUM(B11:M11) -> 57737008 | P11: =O11/$O$3 -> 1
A12: GRANDE NADIA | B12: 2155229 | C12: 4890094 | D12: 14978862 | E12: 2999837 | F12: 69911 | G12: 1471772 | J12: 226723 | K12: 15473393 | L12: 15177338 | M12: 293849 | O12: =SUM(B12:M12) -> 57737008 | P12: =O12/$O$3 -> 1
A13: GUDIÑO GABRIELA | B13: 2155229 | C13: 4890094 | D13: 14978862 | E13: 2999837 | F13: 69911 | G13: 1471772 | J13: 226723 | K13: 15473393 | L13: 15177338 | M13: 293849 | O13: =SUM(B13:M13) -> 57737008 | P13: =O13/$O$3 -> 1
A14: HARRIAGUE LUCIA | B14: 1724183 | C14: 3983872 | D14: 11983089 | E14: 2399870 | F14: 55929 | G14: 1177418 | J14: 181378 | K14: 12378715 | L14: 12141870 | M14: 235079 | O14: =SUM(B14:M14) -> 46261403 | P14: =O14/$O$3 -> 0.80124351
... A23: VELA | B23: 2155229 | C23: 4172118 | D23: 14978862 | E23: 2999837 | F23: 69911 | G23: 1471772 | J23: 226723 | K23: 15473393 | L23: 15177338 | M23: 293849 | O23: =SUM(B23:M23) -> 57019032 | P23: =O23/$O$3 -> 0.98756472
B26: 46059 | C26: 46066 | D26: 46073 | E26: 46080 | J26: 46058 | K26: 46066 | L26: 46079 | M26: 46080 | O26: Totales
A27: ALVAREZ LUCAS | B27: 1978126 | C27: 2681374 | D27: 6539824 | E27: 13113633 | J27: 269636 | K27: 5485195 | L27: 260447 | M27: 14354913 | O27: =SUM(B27:M27) -> 44683148 | P27: =O27/$O$27 -> 1
A28: BURGUEÑO LUCAS | B28: 1978126 | C28: 2681374 | D28: 6539824 | E28: 13113633 | J28: 269636 | K28: 5485195 | L28: 260447 | M28: 14354913 | O28: =SUM(B28:M28) -> 44683148 | P28: =O28/$O$27 -> 1
A29: CASTRO | B29: 1978126 | C29: 2681374 | D29: 6539824 | E29: 13113633 | J29: 269636 | K29: 5485195 | L29: 260447 | M29: 14354913 | O29: =SUM(B29:M29) -> 44683148 | P29: =O29/$O$27 -> 1
A30: CONSIGLI ROBERTO CARLOS | B30: 1978126 | C30: 2681374 | D30: 6539824 | E30: 13113633 | J30: 269636 | K30: 5485195 | L30: 260447 | M30: 14354913 | O30: =SUM(B30:M30) -> 44683148 | P30: =O30/$O$27 -> 1
A31: DEGREEF | B31: 1978126 | C31: 2681374 | D31: 6539824 | E31: 13113633 | J31: 269636 | K31: 5485195 | L31: 260447 | M31: 14354913 | O31: =SUM(B31:M31) -> 44683148 | P31: =O31/$O$27 -> 1
A32: ESPINOSA | B32: 1412947 | C32: 1915267 | D32: 4671303 | E32: 9366881 | J32: 179757 | K32: 3917996 | L32: 173631 | M32: 9796181 | O32: =SUM(B32:M32) -> 31433963 | P32: =O32/$O$27 -> 0.70348586
A33: GARCIA | B33: 1978126 | C33: 2681374 | D33: 6539824 | E33: 13113633 | J33: 269636 | K33: 5485195 | L33: 260447 | M33: 14354913 | O33: =SUM(B33:M33) -> 44683148 | P33: =O33/$O$27 -> 1
A34: GIOJA MARIO ERNESTO | B34: 1412947 | C34: 1915267 | D34: 4671303 | E34: 9366881 | J34: 179757 | K34: 3917996 | L34: 173631 | M34: 9796181 | O34: =SUM(B34:M34) -> 31433963 | P34: =O34/$O$27 -> 0.70348586
A35: GOGORZA NICOLAS | B35: 1978126 | C35: 2681374 | D35: 6539824 | E35: 13113633 | J35: 269636 | K35: 5485195 | L35: 260447 | M35: 14354913 | O35: =SUM(B35:M35) -> 44683148 | P35: =O35/$O$27 -> 1
A36: GRANDE NADIA | B36: 1978126 | C36: 2681374 | D36: 6539824 | E36: 13113633 | J36: 269636 | K36: 5485195 | L36: 260447 | M36: 14354913 | O36: =SUM(B36:M36) -> 44683148 | P36: =O36/$O$27 -> 1
A37: GUDIÑO GABRIELA | B37: 1978126 | C37: 2681374 | D37: 6539824 | E37: 13113633 | J37: 269636 | K37: 5485195 | L37: 260447 | M37: 14354913 | O37: =SUM(B37:M37) -> 44683148 | P37: =O37/$O$27 -> 1
A38: HARRIAGUE LUCIA | B38: 1582501 | C38: 2145099 | D38: 5231859 | E38: 10490907 | J38: 188745 | K38: 4393036 | L38: 182313 | M38: 10523540 | O38: =SUM(B38:M38) -> 34738000 | P38: =O38/$O$27 -> 0.77742956
... A47: VELA | B47: 1978126 | C47: 2681374 | D47: 6539824 | E47: 13113633 | J47: 269636 | K47: 5478223 | L47: 260447 | M47: 14354913 | O47: =SUM(B47:M47) -> 44676176 | P47: =O47/$O$27 -> 0.99984397
B50: 46087 | C50: 46094 | D50: 46101 | E50: 46108 | J50: 46086 | K50: 46097 | L50: 46107 | M50: 46108 | O50: Totales
A51: ALVAREZ LUCAS | B51: 3165356 | C51: 2521313 | D51: 9057207 | E51: 2830726 | J51: 306197 | K51: 7947194 | L51: 38730 | M51: 9916005 | O51: =SUM(B51:M51) -> 35782728 | P51: =O51/$O$51 -> 1
A52: BURGUEÑO LUCAS | B52: 3165356 | C52: 2521313 | D52: 9057207 | E52: 2830726 | J52: 306197 | K52: 7947194 | L52: 38730 | M52: 9916005 | O52: =SUM(B52:M52) -> 35782728 | P52: =O52/$O$51 -> 1
A53: CASTRO | B53: 3165356 | C53: 2521313 | D53: 9057207 | E53: 2830726 | J53: 306197 | K53: 7947194 | L53: 38730 | M53: 9916005 | O53: =SUM(B53:M53) -> 35782728 | P53: =O53/$O$51 -> 1
A54: CONSIGLI ROBERTO CARLOS | B54: 3165356 | C54: 2521313 | D54: 9057207 | E54: 2830726 | J54: 306197 | K54: 7947194 | L54: 38730 | M54: 9916005 | O54: =SUM(B54:M54) -> 35782728 | P54: =O54/$O$51 -> 1
A55: DEGREEF | B55: 3165356 | C55: 2521313 | D55: 9057207 | E55: 2830726 | J55: 306197 | K55: 7947194 | L55: 38730 | M55: 9916005 | O55: =SUM(B55:M55) -> 35782728 | P55: =O55/$O$51 -> 1
A56: ESPINOSA | B56: 2215822 | C56: 1753164 | D56: 6075614 | E56: 1891823 | J56: 204131 | K56: 5521175 | L56: 25820 | M56: 6623360 | O56: =SUM(B56:M56) -> 24310909 | P56: =O56/$O$51 -> 0.67940345
A57: GARCIA | B57: 3165356 | C57: 2521313 | D57: 9057207 | E57: 2830726 | J57: 306197 | K57: 7947194 | L57: 38730 | M57: 9916005 | O57: =SUM(B57:M57) -> 35782728 | P57: =O57/$O$51 -> 1
A58: GIOJA MARIO ERNESTO | B58: 2215822 | C58: 1753164 | D58: 6075614 | E58: 1891823 | J58: 204131 | K58: 5521175 | L58: 25820 | M58: 6623360 | O58: =SUM(B58:M58) -> 24310909 | P58: =O58/$O$51 -> 0.67940345
A59: GOGORZA NICOLAS | B59: 3165356 | C59: 2521313 | D59: 9057207 | E59: 2830726 | J59: 306197 | K59: 7947194 | L59: 38730 | M59: 9916005 | O59: =SUM(B59:M59) -> 35782728 | P59: =O59/$O$51 -> 1
A60: GRANDE NADIA | B60: 3165356 | C60: 2521313 | D60: 9057207 | E60: 2830726 | J60: 306197 | K60: 7947194 | L60: 38730 | M60: 9916005 | O60: =SUM(B60:M60) -> 35782728 | P60: =O60/$O$51 -> 1
A61: GUDIÑO GABRIELA | B61: 3165356 | C61: 2521313 | D61: 9057207 | E61: 2830726 | J61: 306197 | K61: 7947194 | L61: 38730 | M61: 9916005 | O61: =SUM(B61:M61) -> 35782728 | P61: =O61/$O$51 -> 1
...

Sheet 2025
B1: 02/01 | C1: 10/01 | D1: 17/01 | E1: 45678 | F1: 45680 | G1: 45688 | J1: 45662 | K1: 45672 | L1: 45685 | M1: 45688 | O1: Totales
A2: ALVAREZ LUCAS | B2: 924914 | C2: 772916 | D2: 10359260 | E2: 398879 | F2: 4173672 | G2: 5557400 | K2: 20929433 | L2: 337408 | M2: 9945079 | O2: =SUM(B2:N2) -> 53398961 | P2: =O2/$O$2 -> 1
A3: BURGUEÑO LUCAS | B3: 924914 | C3: 772916 | D3: 10359260 | E3: 398879 | F3: 4173672 | G3: 5557400 | K3: 20929433 | L3: 337408 | M3: 9945079 | O3: =SUM(B3:N3) -> 53398961 | P3: =O3/$O$2 -> 1
A4: CASTRO | B4: 924914 | C4: 772916 | D4: 9858028 | E4: 398879 | F4: 4173672 | G4: 5447158 | K4: 20893708 | L4: 337408 | M4: 9914336 | O4: =SUM(B4:N4) -> 52721019 | P4: =O4/$O$2 -> 0.98730421
A5: CONSIGLI ROBERTO CARLOS | B5: 924914 | C5: 772916 | D5: 10359260 | E5: 398879 | F5: 4173672 | G5: 5557400 | K5: 20929433 | L5: 337408 | M5: 9945079 | O5: =SUM(B5:N5) -> 53398961 | P5: =O5/$O$2 -> 1
A6: DEGREEF | B6: 924914 | C6: 772916 | D6: 10359260 | E6: 319386 | F6: 4173672 | G6: 5557400 | K6: 20929433 | L6: 337408 | M6: 9945079 | O6: =SUM(B6:N6) -> 53319468 | P6: =O6/$O$2 -> 0.99851134
A7: ESPINOSA | B7: 660653 | C7: 552082 | D7: 7399471 | E7: 364407 | F7: 2981194 | G7: 3969571 | K7: 14949595 | L7: 241006 | M7: 7103628 | O7: =SUM(B7:N7) -> 38221607 | P7: =O7/$O$2 -> 0.71577436
A8: GARCIA | B8: 924914 | C8: 772916 | D8: 10359260 | E8: 398879 | F8: 4173672 | G8: 5557400 | K8: 20929433 | L8: 337408 | M8: 9945079 | O8: =SUM(B8:N8) -> 53398961 | P8: =O8/$O$2 -> 1
A9: GIOJA MARIO ERNESTO | B9: 660653 | C9: 552082 | D9: 7399471 | E9: 284914 | F9: 2981194 | G9: 3969571 | K9: 14949595 | L9: 241006 | M9: 7103628 | O9: =SUM(B9:N9) -> 38142114 | P9: =O9/$O$2 -> 0.7142857
A10: GOGORZA NICOLAS | B10: 924914 | C10: 772916 | D10: 10359260 | E10: 398879 | F10: 4173672 | G10: 5557400 | K10: 20929433 | L10: 337408 | M10: 9945079 | O10: =SUM(B10:N10) -> 53398961 | P10: =O10/$O$2 -> 1
A11: GRANDE NADIA | B11: 924914 | C11: 772916 | D11: 10359260 | E11: 398879 | F11: 4173672 | G11: 5557400 | K11: 20929433 | L11: 337408 | M11: 9945079 | O11: =SUM(B11:N11) -> 53398961 | P11: =O11/$O$2 -> 1
A12: GUDIÑO GABRIELA | B12: 924914 | C12: 772916 | D12: 10359260 | E12: 398879 | F12: 4173672 | G12: 5557400 | K12: 20929433 | L12: 337408 | M12: 9945079 | O12: =SUM(B12:N12) -> 53398961 | P12: =O12/$O$2 -> 1
A13: HARRIAGUE LUCIA | B13: 832423 | C13: 695624 | D13: 9327007 | E13: 358991 | F13: 3756305 | G13: 5001660 | K13: 18836489 | L13: 303667 | M13: 8953645 | O13: =SUM(B13:N13) -> 48065811 | P13: =O13/$O$2 -> 0.90012633
... A22: VELA | B22: 660653 | C22: 493355 | D22: 6008896 | E22: 238479 | F22: 2115302 | G22: 2032738 | K22: 12798959 | L22: 241006 | M22: 7000039 | O22: =SUM(B22:N22) -> 31589427 | P22: =O22/$O$2 -> 0.59157381
B25: 45694 | C25: 45701 | D25: 45702 | E25: 45709 | F25: 45716 | J25: 45693 | K25: 45702 | L25: 45714 | M25: 45716 | O25: Totales
A26: ALVAREZ LUCAS | B26: 761142 | C26: 6758529.1 | D26: 362017 | E26: 8927555.4 | F26: 3778811.5 | J26: 59184.47 | K26: 3222290.4 | L26: 297005.06 | M26: 9311433.2 | O26: =SUM(B26:N26) -> 33477968 | P26: =O26/$O$26 -> 1
A27: BURGUEÑO LUCAS | B27: 761142 | C27: 6758529.1 | D27: 362017 | E27: 8927555.4 | F27: 3778811.5 | J27: 59184.47 | K27: 3222290.4 | L27: 297005.06 | M27: 9311433.2 | O27: =SUM(B27:N27) -> 33477968 | P27: =O27/$O$26 -> 1
A28: CASTRO | B28: 726195 | C28: 6758529.1 | D28: 362017 | E28: 8927555.4 | F28: 3778811.5 | J28: 59184.47 | K28: 3212040.7 | L28: 297005.06 | M28: 9311433.2 | O28: =SUM(B28:N28) -> 33432771 | P28: =O28/$O$26 -> 0.99864996
A29: CONSIGLI ROBERTO CARLOS | B29: 761142 | C29: 6758529.1 | D29: 362017 | E29: 8927555.4 | F29: 3778811.5 | J29: 59184.47 | K29: 3222290.4 | L29: 297005.06 | M29: 9311433.2 | O29: =SUM(B29:N29) -> 33477968 | P29: =O29/$O$26 -> 1
A30: DEGREEF | B30: 761142 | C30: 6758529.1 | D30: 362017 | E30: 8927555.4 | F30: 3778811.5 | J30: 59184.47 | K30: 3222290.4 | L30: 297005.06 | M30: 9311433.2 | O30: =SUM(B30:N30) -> 33477968 | P30: =O30/$O$26 -> 1
A31: ESPINOSA | B31: 543672 | C31: 4827520.8 | D31: 258583 | E31: 6376825.3 | F31: 2699151.1 | J31: 42274.62 | K31: 2301636 | L31: 212146.47 | M31: 6651023.7 | O31: =SUM(B31:N31) -> 23912833 | P31: =O31/$O$26 -> 0.71428567
A32: GARCIA | B32: 761142 | C32: 6758529.1 | D32: 362017 | E32: 8927555.4 | F32: 3778811.5 | J32: 59184.47 | K32: 3222290.4 | L32: 297005.06 | M32: 9311433.2 | O32: =SUM(B32:N32) -> 33477968 | P32: =O32/$O$26 -> 1
A33: GIOJA MARIO ERNESTO | B33: 543672 | C33: 4827520.8 | D33: 258583 | E33: 6376825.3 | F33: 2699151.1 | J33: 42274.62 | K33: 2301636 | L33: 212146.47 | M33: 6651023.7 | O33: =SUM(B33:N33) -> 23912833 | P33: =O33/$O$26 -> 0.71428567
A34: GOGORZA NICOLAS | B34: 761142 | C34: 6758529.1 | D34: 362017 | E34: 8927555.4 | F34: 3778811.5 | J34: 59184.47 | K34: 3222290.4 | L34: 297005.06 | M34: 9311433.2 | O34: =SUM(B34:N34) -> 33477968 | P34: =O34/$O$26 -> 1
A35: GRANDE NADIA | B35: 761142 | C35: 6758529.1 | D35: 362017 | E35: 8927555.4 | F35: 3778811.5 | J35: 59184.47 | K35: 3222290.4 | L35: 297005.06 | M35: 9311433.2 | O35: =SUM(B35:N35) -> 33477968 | P35: =O35/$O$26 -> 1
A36: GUDIÑO GABRIELA | B36: 761142 | C36: 6758529.1 | D36: 362017 | E36: 8927555.4 | F36: 3778811.5 | J36: 59184.47 | K36: 3222290.4 | L36: 297005.06 | M36: 9311433.2 | O36: =SUM(B36:N36) -> 33477968 | P36: =O36/$O$26 -> 1
A37: HARRIAGUE LUCIA | B37: 685027 | C37: 6082676.2 | D37: 325815 | E37: 8034799.9 | F37: 3400930.3 | J37: 53266.02 | K37: 2901086.4 | L37: 267304.56 | M37: 8380289.9 | O37: =SUM(B37:N37) -> 30131195 | P37: =O37/$O$26 -> 0.90003058
... A41: SAN MARTIN | B41: 761142 | C41: 6758529.1 | D41: 362017 | E41: 8927555.4 | F41: 3778811.5 | J41: 59184.47 | K41: 3222290.4 | L41: 297005.06 | M41: 9311433.2 | O41: =SUM(B41:N41) -> 33477968 | P41: =O41/$O$26 -> 1
A42: SALVAREZZA | B42: 308012 | C42: 5713446.7 | D42: $ - | E42: 7131435.1 | F42: 2664559.6 | J42: 50729.54 | K42: 2699841.5 | L42: 254575.77 | M42: 7913335.1 | O42: =SUM(B42:N42) -> 26735935 | P42: =O42/$O$26 -> 0.79861284
A43: SCHVARTZMAN MATIAS | B43: 761142 | C43: 6758529.1 | D43: 362017 | E43: 8927555.4 | F43: 3778811.5 | J43: 59184.47 | K43: 3222290.4 | L43: 297005.06 | M43: 9311433.2 | O43: =SUM(B43:N43) -> 33477968 | P43: =O43/$O$26 -> 1
A44: SERRANO GAMARRA JUAN | B44: 691680 | C44: 6758529.1 | D44: 362017 | E44: 8907986 | F44: 3739306.6 | J44: 59184.47 | K44: 3207795.4 | L44: 297005.06 | M44: 9296475.2 | O44: =SUM(B44:N44) -> 33319979 | P44: =O44/$O$26 -> 0.9952808
A45: TOTIS | B45: 761142 | C45: 6758529.1 | D45: 362017 | E45: 8927555.4 | F45: 3778811.5 | J45: 59184.47 | K45: 3222290.4 | L45: 297005.06 | M45: 9311433.2 | O45: =SUM(B45:N45) -> 33477968 | P45: =O45/$O$26 -> 1
A46: VELA | B46: 273466 | C46: 4823948.1 | D46: $ - | E46: 6100344.1 | F46: 2455708.4 | J46: 50729.54 | K46: 2249868 | L46: 254575.77 | M46: 7606227.1 | O46: =SUM(B46:N46) -> 23814867 | P46: =O46/$O$26 -> 0.71135939
B49: 45722 | C49: 45730 | D49: 45736 | E49: 45737 | F49: 45743 | G49: 45744 | J49: 45721 | K49: 45730 | L49: 45743 | M49: 45747 | O49: Totales
A50: ALVAREZ LUCAS | B50: 664347.31 | C50: 1606627.3 | D50: 9287868.5 | E50: 78118.88 | F50: 43598.13 | G50: 4262242.9 | J50: 59784.02 | K50: 1606627.3 | L50: 124039 | M50: 12818004 | O50: =SUM(B50:N50) -> 30551257 | P50: =O50/$O$50 -> 1
A51: BURGUEÑO LUCAS | B51: 664347.31 | C51: 1606627.3 | D51: 9287868.5 | E51: 78118.88 | F51: 43598.13 | G51: 4262242.9 | J51: 59784.02 | K51: 1606627.3 | L51: 124039 | M51: 12818004 | O51: =SUM(B51:N51) -> 30551257 | P51: =O51/$O$50 -> 1
A52: CASTRO | B52: 664347.31 | C52: 1606627.3 | D52: 9287868.5 | E52: 78118.88 | F52: 43598.13 | G52: 4262242.9 | J52: 59784.02 | K52: 1606627.3 | L52: 124039 | M52: 12818004 | O52: =SUM(B52:N52) -> 30551257 | P52: =O52/$O$50 -> 1
A53: CONSIGLI ROBERTO CARLOS | B53: 664347.31 | C53: 1606627.3 | D53: 9287868.5 | E53: 78118.88 | F53: 43598.13 | G53: 4262242.9 | J53: 59784.02 | K53: 1606627.3 | L53: 124039 | M53: 12818004 | O53: =SUM(B53:N53) -> 30551257 | P53: =O53/$O$50 -> 1
A54: DEGREEF | B54: 664347.31 | C54: 1606627.3 | D54: 9287868.5 | E54: 78118.88 | F54: 43598.13 | G54: 4262242.9 | J54: 59784.02 | K54: 1606627.3 | L54: 124039 | M54: 12818004 | O54: =SUM(B54:N54) -> 30551257 | P54: =O54/$O$50 -> 1
A55: ESPINOSA | B55: 474533.8 | C55: 1147590.9 | D55: 6634191.8 | E55: 55799.2 | F55: 31141.52 | G55: 3044459.2 | J55: 42702.87 | K55: 1147590.9 | L55: 88599 | M55: 9155717 | O55: =SUM(B55:N55) -> 21822326 | P55: =O55/$O$50 -> 0.7142857
...

Sheet 2024
A1: Socio | B1: ADV 0401 | C1: ADV 1201 | D1: ADV 1901 | E1: ADV 2601 | F1: ADV 2112 | H1: NQN 0501 | I1: NQN 1501 | J1: NQN 2601 | K1: NQN 3101 | M1: Totales | N1: Columna2 | O1: Columna3 | P1: Columna4
A2: ALVAREZ LUCAS | B2: 745983.26 | C2: 1583630.9 | D2: 464600.74 | E2: 1127053.6 | H2: 102515.27 | I2: 1803386.7 | J2: 164980.95 | K2: 2985589.6 | M2: =SUM(B2:L2) -> 8977741 | N2: =M2/SUM($M$2:$M$19) -> 0.059079724 | O2: =N2/$N$2 -> 1 | P2: ALVAREZ LUCAS
A3: BURGUEÑO LUCAS | B3: 745983.26 | C3: 1583630.9 | D3: 464600.74 | E3: 1127053.6 | H3: 102515.27 | I3: 1803386.7 | J3: 164980.95 | K3: 2985589.6 | M3: =SUM(B3:L3) -> 8977741 | N3: =M3/SUM($M$2:$M$19) -> 0.059079724 | O3: =N3/$N$2 -> 1 | P3: BURGUEÑO LUCAS
A4: CONSIGLI ROBERTO CARLOS | B4: 745983.26 | C4: 1583630.9 | D4: 464600.74 | E4: 1127053.6 | H4: 102515.27 | I4: 1803386.7 | J4: 164980.95 | K4: 2985589.6 | M4: =SUM(B4:L4) -> 8977741 | N4: =M4/SUM($M$2:$M$19) -> 0.059079724 | O4: =N4/$N$2 -> 1 | P4: CONSIGLI ROBERTO CARLOS
A5: DEGREEF | B5: 474107.84 | C5: 1008168.5 | D5: 397520.19 | E5: 1147709.3 | H5: 94356.309 | I5: 1798947.8 | J5: 164980.95 | K5: 2976993.3 | M5: =SUM(B5:L5) -> 8062784.1 | N5: =M5/SUM($M$2:$M$19) -> 0.053058677 | O5: =N5/$N$2 -> 0.89808607 | P5: DEGREEF
A6: ESPINOSA | B6: 653200.8 | C6: 1378432.2 | D6: 354321.74 | E6: 855930.84 | H6: 76024.448 | I6: 1311519.6 | J6: 117843.53 | K6: 2412214.2 | M6: =SUM(B6:L6) -> 7159487.4 | N6: =M6/SUM($M$2:$M$19) -> 0.047114362 | O6: =N6/$N$2 -> 0.79747092 | P6: ESPINOSA
A7: GARCIA | B7: 745983.26 | C7: 1583630.9 | D7: 464600.74 | E7: 1127053.6 | H7: 102515.27 | I7: 1803386.7 | J7: 164980.95 | K7: 2985589.6 | M7: =SUM(B7:L7) -> 8977741 | N7: =M7/SUM($M$2:$M$19) -> 0.059079724 | O7: =N7/$N$2 -> 1 | P7: GARCIA
A8: GIOJA MARIO ERNESTO | B8: 541846.76 | C8: 1150951.3 | D8: 345093.19 | E8: 820974.2 | H8: 73556.903 | I8: 1304370.2 | J8: 117843.53 | K8: 2157223 | M8: =SUM(B8:L8) -> 6511859.1 | N8: =M8/SUM($M$2:$M$19) -> 0.042852521 | O8: =N8/$N$2 -> 0.72533382 | P8: GIOJA MARIO ERNESTO
A9: GOGORZA NICOLAS | B9: 745983.26 | C9: 1583630.9 | D9: 464600.74 | E9: 1127053.6 | H9: 102515.27 | I9: 1803386.7 | J9: 164980.95 | K9: 2985589.6 | M9: =SUM(B9:L9) -> 8977741 | N9: =M9/SUM($M$2:$M$19) -> 0.059079724 | O9: =N9/$N$2 -> 1 | P9: GOGORZA NICOLAS
A10: GRANDE NADIA | B10: 745983.26 | C10: 1583630.9 | D10: 464600.74 | E10: 1127053.6 | H10: 102515.27 | I10: 1803386.7 | J10: 164980.95 | K10: 2985589.6 | M10: =SUM(B10:L10) -> 8977741 | N10: =M10/SUM($M$2:$M$19) -> 0.059079724 | O10: =N10/$N$2 -> 1 | P10: GRANDE NADIA
A11: GUDIÑO GABRIELA | B11: 745983.26 | C11: 1583630.9 | D11: 464600.74 | E11: 1127053.6 | H11: 102515.27 | I11: 1803386.7 | J11: 164980.95 | K11: 2985589.6 | M11: =SUM(B11:L11) -> 8977741 | N11: =M11/SUM($M$2:$M$19) -> 0.059079724 | O11: =N11/$N$2 -> 1 | P11: GUDIÑO GABRIELA
A12: HARRIAGUE LUCIA | B12: 564601.75 | C12: 1206686 | D12: 339135.24 | E12: 848859.25 | H12: 95126.735 | I12: 1347666 | J12: 164980.95 | K12: 2550034.4 | M12: =SUM(B12:L12) -> 7117090.3 | N12: =M12/SUM($M$2:$M$19) -> 0.04683536 | O12: =N12/$N$2 -> 0.79274846 | P12: HARRIAGUE LUCIA
A13: MACIAS | B13: 745983.26 | C13: 1583630.9 | D13: 464600.74 | E13: 1127053.6 | H13: 102515.27 | I13: 1803386.7 | J13: 164980.95 | K13: 2985589.6 | M13: =SUM(B13:L13) -> 8977741 | N13: =M13/SUM($M$2:$M$19) -> 0.059079724 | O13: =N13/$N$2 -> 1 | P13: MACIAS
... A19: TOTIS | B19: 718521.94 | C19: 1459779.2 | D19: 401406.03 | E19: 1073859.8 | H19: 99478.115 | I19: 1356646.8 | J19: 164980.95 | K19: 2911513 | M19: =SUM(B19:L19) -> 8186185.8 | N19: =M19/SUM($M$2:$M$19) -> 0.053870745 | O19: =N19/$N$2 -> 0.91183137 | P19: TOTIS
A20: TOTALES | B20: =SUM(B2:B19) -> 12500836 | C20: =SUM(C2:C19) -> 26474492 | D20: =SUM(D2:D19) -> 7790946 | E20: =SUM(E2:E19) -> 19174343 | F20: =SUM(F2:F19) -> 0 | G20: =SUM(G2:G19) -> 0 | H20: =SUM(H2:H19) -> 1750737.9 | I20: =SUM(I2:I19) -> 30202500 | ... N20: =SUM(N2:N19) -> 1
A23: Socio | B23: ADV 0202 | C23: ADV 0902 | D23: ADV 1602 | E23: ADV 2302 | F23: ADV 2802 | G23: ADV0103 | H23: NQN 0502 | I23: NQN 1602 | J23: NQN 2602 | K23: NQN 2902 | M23: Totales | N23: Columna2 | O23: Columna3 | P23: Columna4
A24: ALVAREZ LUCAS | B24: 472240.28 | C24: 1659869.2 | D24: 2706373.5 | E24: 1398561.4 | F24: 68863.461 | G24: 448001.15 | H24: 0 | I24: 3946566.2 | J24: 37038.084 | K24: 2590955 | M24: =SUM(B24:L24) -> 13328468 | N24: =M24/SUM($M$24:$M$41) -> 0.058665381 | O24: =N24/$N$24 -> 1 | P24: ALVAREZ LUCAS
A25: BURGUEÑO LUCAS | B25: 472240.28 | C25: 1659869.2 | D25: 2706373.5 | E25: 1398561.4 | F25: 68863.461 | G25: 448001.15 | H25: 0 | I25: 3946566.2 | J25: 37038.084 | K25: 2590955 | M25: =SUM(B25:L25) -> 13328468 | N25: =M25/SUM($M$24:$M$41) -> 0.058665381 | O25: =N25/$N$24 -> 1 | P25: BURGUEÑO LUCAS
A26: CONSIGLI ROBERTO CARLOS | B26: 472240.28 | C26: 1659869.2 | D26: 2706373.5 | E26: 1398561.4 | F26: 68863.461 | G26: 448001.15 | H26: 0 | I26: 3946566.2 | J26: 37038.084 | K26: 2590955 | M26: =SUM(B26:L26) -> 13328468 | N26: =M26/SUM($M$24:$M$41) -> 0.058665381 | O26: =N26/$N$24 -> 1 | P26: CONSIGLI ROBERTO CARLOS
A27: DEGREEF | B27: 414843.54 | C27: 1653214.8 | D27: 2700330.7 | E27: 1398561.4 | F27: 68863.461 | G27: 448001.15 | H27: 0 | I27: 3939140.5 | J27: 37038.084 | K27: 2590955 | M27: =SUM(B27:L27) -> 13250949 | N27: =M27/SUM($M$24:$M$41) -> 0.058324178 | O27: =N27/$N$24 -> 0.9941839 | P27: DEGREEF
A28: ESPINOSA | B28: 379117.79 | C28: 1228723.4 | D28: 1975072.9 | E28: 1018035.4 | F28: 49188.187 | G28: 320000.82 | H28: 0 | I28: 2822158.7 | J28: 26455.774 | K28: 1851223.8 | M28: =SUM(B28:L28) -> 9669976.7 | N28: =M28/SUM($M$24:$M$41) -> 0.042562495 | O28: =N28/$N$24 -> 0.72551297 | P28: ESPINOSA
A29: GARCIA | B29: 472240.28 | C29: 1659869.2 | D29: 2706373.5 | E29: 1398561.4 | F29: 68863.461 | G29: 448001.15 | H29: 0 | I29: 3946566.2 | J29: 37038.084 | K29: 2590955 | M29: =SUM(B29:L29) -> 13328468 | N29: =M29/SUM($M$24:$M$41) -> 0.058665381 | O29: =N29/$N$24 -> 1 | P29: GARCIA
A30: GIOJA MARIO ERNESTO | B30: 342083.11 | C30: 1205588.5 | D30: 1969697.3 | E30: 1006871.3 | F30: 49188.187 | G30: 320000.82 | H30: 0 | I30: 2820153.7 | J30: 26455.774 | K30: 1851210.5 | M30: =SUM(B30:L30) -> 9591249.2 | N30: =M30/SUM($M$24:$M$41) -> 0.042215975 | O30: =N30/$N$24 -> 0.71960625 | P30: GIOJA MARIO ERNESTO
A31: GOGORZA NICOLAS | B31: 472240.28 | C31: 1659869.2 | D31: 2706373.5 | E31: 1398561.4 | F31: 68863.461 | G31: 448001.15 | H31: 0 | I31: 3946566.2 | J31: 37038.084 | K31: 2590955 | M31: =SUM(B31:L31) -> 13328468 | N31: =M31/SUM($M$24:$M$41) -> 0.058665381 | O31: =N31/$N$24 -> 1 | P31: GOGORZA NICOLAS
A32: GRANDE NADIA | B32: 472240.28 | C32: 1659869.2 | D32: 2706373.5 | E32: 1398561.4 | F32: 68863.461 | G32: 448001.15 | H32: 0 | I32: 3946566.2 | J32: 37038.084 | K32: 2590955 | M32: =SUM(B32:L32) -> 13328468 | N32: =M32/SUM($M$24:$M$41) -> 0.058665381 | O32: =N32/$N$24 -> 1 | P32: GRANDE NADIA
A33: GUDIÑO GABRIELA | B33: 472240.28 | C33: 1659869.2 | D33: 2706373.5 | E33: 1398561.4 | F33: 68863.461 | G33: 448001.15 | H33: 0 | I33: 3946566.2 | J33: 37038.084 | K33: 2590955 | M33: =SUM(B33:L33) -> 13328468 | N33: =M33/SUM($M$24:$M$41) -> 0.058665381 | O33: =N33/$N$24 -> 1 | P33: GUDIÑO GABRIELA
A34: HARRIAGUE LUCIA | B34: 372244.49 | C34: 1312161.4 | D34: 2055219.4 | E34: 1228229.6 | F34: 62869.197 | G34: 444727.29 | H34: 0 | I34: 3902234.7 | J34: 37038.084 | K34: 2579137.9 | M34: =SUM(B34:L34) -> 11993862 | N34: =M34/SUM($M$24:$M$41) -> 0.052791099 | O34: =N34/$N$24 -> 0.899868 | P34: HARRIAGUE LUCIA
A35: MACIAS | B35: 472240.28 | C35: 1659869.2 | D35: 2706373.5 | E35: 1398561.4 | F35: 68863.461 | G35: 448001.15 | H35: 0 | I35: 3946566.2 | J35: 37038.084 | K35: 2590955 | M35: =SUM(B35:L35) -> 13328468 | N35: =M35/SUM($M$24:$M$41) -> 0.058665381 | O35: =N35/$N$24 -> 1 | P35: MACIAS
... A38: SAN MARTIN | B38: 472240.28 | C38: 1659869.2 | D38: 2706373.5 | E38: 1398561.4 | F38: 68863.461 | G38: 448001.15 | H38: 0 | I38: 3946566.2 | J38: 37038.084 | K38: 2590955 | M38: =SUM(B38:L38) -> 13328468 | N38: =M38/SUM($M$24:$M$41) -> 0.058665381 | O38: =N38/$N$24 -> 1 | P38: SAN MARTIN
A39: SCHVARTZMAN MATIAS | B39: 472240.28 | C39: 1659869.2 | D39: 2706373.5 | E39: 1398561.4 | F39: 68863.461 | G39: 448001.15 | H39: 0 | I39: 3946566.2 | J39: 37038.084 | K39: 2590955 | M39: =SUM(B39:L39) -> 13328468 | N39: =M39/SUM($M$24:$M$41) -> 0.058665381 | O39: =N39/$N$24 -> 1 | P39: SCHVARTZMAN MATIAS | V39: 0.6667 | W39: =V46*V39 -> 10131523
A40: SERRANO GAMARRA JUAN | B40: 377792.22 | C40: 1328641.4 | D40: 2165059 | E40: 1118849.2 | F40: 55090.769 | G40: 358400.92 | H40: 0 | I40: 3157253 | J40: 29630.467 | K40: 2072764 | M40: =SUM(B40:L40) -> 10663481 | N40: =M40/SUM($M$24:$M$41) -> 0.046935414 | O40: =N40/$N$24 -> 0.80005299 | P40: SERRANO GAMARRA JUAN | U40: =(M42+M64+M86)/3 -> 2.7737427e+08 | V40: =15 -> 15 | Y40: 15
A41: TOTIS | B41: 447486.59 | C41: 1384667.6 | D41: 1920560.7 | E41: 1281687.4 | F41: 68863.461 | G41: 448001.15 | H41: 0 | I41: 3912801.6 | J41: 37038.084 | K41: 2582534.2 | M41: =SUM(B41:L41) -> 12083641 | N41: =M41/SUM($M$24:$M$41) -> 0.053186261 | O41: =N41/$N$24 -> 0.90660386 | P41: TOTIS | V41: =3*0.6667 -> 2.0001 | Y41: =0.7142*2 -> 1.4284 | Z41: =Y41*Y46/2 -> 11498497
A42: TOTALES | B42: =SUM(B24:B41) -> 8000451.1 | C42: =SUM(C24:C41) -> 28031428 | D42: =SUM(D24:D41) -> 45262422 | E42: =SUM(E24:E41) -> 23834972 | F42: =SUM(F24:F41) -> 1180424.8 | G42: =SUM(G24:G41) -> 7715145.9 | H42: =SUM(H24:H41) -> 0 | I42: =SUM(I24:I41) -> 67912536 | ... N42: =SUM(N24:N41) -> 1 | V42: 0.5 | W42: =V46*V42 -> 7598262.2 | Y42: 0.8
V43: =0.8-(5/7-4/6) -> 0.75238095 | W43: =V46*V43 -> 11433575 | Y43: =SUM(Y40:Y42) -> 17.2284
V44: =SUM(V40:V43) -> 18.252481
A45: Socio | B45: ADV 0803 | C45: ADV 1503 | D45: ADV 2203 | E45: ADV 2803 | H45: NQN 0503 | I45: NQN 1503 | J45: NQN 2603 | K45: NQN 2703 | M45: Totales | N45: Columna2 | O45: Columna3 | P45: Columna4
A46: ALVAREZ LUCAS | B46: 1411169.4 | C46: 900999.29 | D46: 1517193.8 | E46: 1783380 | H46: 42572.189 | I46: 6825219.5 | J46: 48411.547 | K46: 4175701.6 | M46: =SUM(B46:L46) -> 16704647 | N46: =M46/SUM($M$46:$M$63) -> 0.058673112 | O46: =N46/$N$46 -> 1 | P46: ALVAREZ LUCAS | V46: =U40/V44 -> 15196524 | Y46: =U40/Y43 -> 16099828
A47: BURGUEÑO LUCAS | B47: 1411169.4 | C47: 900999.29 | D47: 1517193.8 | E47: 1783380 | H47: 42572.189 | I47: 6825219.5 | J47: 48411.547 | K47: 4175701.6 | M47: =SUM(B47:L47) -> 16704647 | N47: =M47/SUM($M$46:$M$63) -> 0.058673112 | O47: =N47/$N$46 -> 1 | P47: BURGUEÑO LUCAS
A48: CONSIGLI ROBERTO CARLOS | B48: 1411169.4 | C48: 900999.29 | D48: 1517193.8 | E48: 1783380 | H48: 42572.189 | I48: 6825219.5 | J48: 48411.547 | K48: 4175701.6 | M48: =SUM(B48:L48) -> 16704647 | N48: =M48/SUM($M$46:$M$63) -> 0.058673112 | O48: =N48/$N$46 -> 1 | P48: CONSIGLI ROBERTO CARLOS
A49: DEGREEF | B49: 1411169.4 | C49: 900999.29 | D49: 1518051.5 | E49: 1783380 | H49: 42572.189 | I49: 6823428.9 | J49: 48411.547 | K49: 4175701.6 | M49: =SUM(B49:L49) -> 16703714 | N49: =M49/SUM($M$46:$M$63) -> 0.058669835 | O49: =N49/$N$46 -> 0.99994415 | P49: DEGREEF
...

Sheet 2023
B1: ADV 0901 | C1: ADV 2001 | D1: ADV 2701 | E1: ADV | F1: ADV2 | G1: NQN 1301 | H1: NQN 2301 | I1: NQN 2701 | J1: NQN 3101 | K1: NQN | L1: Totales
A2: ALVAREZ LUCAS | B2: 304803.42 | C2: 875553.76 | D2: 239516.61 | G2: 371938.61 | H2: 29623.501 | I2: 7272.0841 | J2: 1502375.1 | L2: =SUM(B2:J2) -> 3331083.1 | M2: =L2/SUM(L$2:L$18) -> 0.062574907
A3: BURGUEÑO LUCAS | B3: 304721.68 | C3: 875553.76 | D3: 239511.52 | G3: 381726.42 | H3: 29623.501 | I3: 7272.0841 | J3: 1502375.1 | L3: =SUM(B3:J3) -> 3340784.1 | M3: =L3/SUM(L$2:L$18) -> 0.062757141
A4: CONSIGLI ROBERTO CARLOS | B4: 304542.48 | C4: 875553.76 | D4: 239500.38 | G4: 392232.3 | H4: 29623.501 | I4: 7272.0841 | J4: 1502375.1 | L4: =SUM(B4:J4) -> 3351099.6 | M4: =L4/SUM(L$2:L$18) -> 0.06295092
A5: ESPINOSA | B5: 106223.09 | C5: 124286.53 | D5: 121987.56 | G5: 311692.93 | H5: 0 | I5: 7272.0841 | J5: 837255.99 | L5: =SUM(B5:J5) -> 1508718.2 | M5: =L5/SUM(L$2:L$18) -> 0.028341502
A6: GARCIA | B6: 304542.48 | C6: 875553.76 | D6: 239500.38 | G6: 392232.3 | H6: 29623.501 | I6: 7272.0841 | J6: 1502375.1 | L6: =SUM(B6:J6) -> 3351099.6 | M6: =L6/SUM(L$2:L$18) -> 0.06295092
A7: GIOJA MARIO ERNESTO | B7: 304542.48 | C7: 875553.76 | D7: 239500.38 | G7: 392232.3 | H7: 29623.501 | I7: 7272.0841 | J7: 1502375.1 | L7: =SUM(B7:J7) -> 3351099.6 | M7: =L7/SUM(L$2:L$18) -> 0.06295092 | O7: =L2/354 -> 9409.8393
A8: GOGORZA NICOLAS | B8: 304542.48 | C8: 875553.76 | D8: 239500.38 | G8: 392232.3 | H8: 29623.501 | I8: 7272.0841 | J8: 1502375.1 | L8: =SUM(B8:J8) -> 3351099.6 | M8: =L8/SUM(L$2:L$18) -> 0.06295092
A9: GRANDE NADIA | B9: 304542.48 | C9: 875553.76 | D9: 239500.38 | G9: 392232.3 | H9: 29623.501 | I9: 7272.0841 | J9: 1502375.1 | L9: =SUM(B9:J9) -> 3351099.6 | M9: =L9/SUM(L$2:L$18) -> 0.06295092
A10: GUDIÑO GABRIELA | B10: 304542.48 | C10: 875553.76 | D10: 239500.38 | G10: 392232.3 | H10: 29623.501 | I10: 7272.0841 | J10: 1502375.1 | L10: =SUM(B10:J10) -> 3351099.6 | M10: =L10/SUM(L$2:L$18) -> 0.06295092
A11: HARRIAGUE LUCIA | B11: 304542.48 | C11: 875553.76 | D11: 239500.38 | G11: 392232.3 | H11: 29623.501 | I11: 7272.0841 | J11: 1502375.1 | L11: =SUM(B11:J11) -> 3351099.6 | M11: =L11/SUM(L$2:L$18) -> 0.06295092
A12: MACIAS | B12: 304542.48 | C12: 875553.76 | D12: 239500.38 | G12: 392232.3 | H12: 29623.501 | I12: 7272.0841 | J12: 1502375.1 | L12: =SUM(B12:J12) -> 3351099.6 | M12: =L12/SUM(L$2:L$18) -> 0.06295092
A13: MELO MAURO | B13: 304542.48 | C13: 875553.76 | D13: 239500.38 | G13: 392232.3 | H13: 29623.501 | I13: 7272.0841 | J13: 1502375.1 | L13: =SUM(B13:J13) -> 3351099.6 | M13: =L13/SUM(L$2:L$18) -> 0.06295092
A14: QUIROGA MARTIN | B14: 304542.48 | C14: 875553.76 | D14: 239500.38 | G14: 392232.3 | H14: 29623.501 | I14: 7272.0841 | J14: 1502375.1 | L14: =SUM(B14:J14) -> 3351099.6 | M14: =L14/SUM(L$2:L$18) -> 0.06295092
A15: SAN MARTIN | B15: 304542.48 | C15: 875553.76 | D15: 239500.38 | G15: 392232.3 | H15: 29623.501 | I15: 7272.0841 | J15: 1502375.1 | L15: =SUM(B15:J15) -> 3351099.6 | M15: =L15/SUM(L$2:L$18) -> 0.06295092
A16: SCHVARTZMAN MATIAS | B16: 304753.24 | C16: 875553.76 | D16: 239513.48 | G16: 371938.61 | H16: 29623.501 | I16: 7272.0841 | J16: 1502375.1 | L16: =SUM(B16:J16) -> 3331029.8 | M16: =L16/SUM(L$2:L$18) -> 0.062573905
A17: SERRANO GAMARRA JUAN | B17: 304542.48 | C17: 875553.76 | D17: 239500.38 | G17: 392232.3 | H17: 29623.501 | I17: 7272.0841 | J17: 1502375.1 | L17: =SUM(B17:J17) -> 3351099.6 | M17: =L17/SUM(L$2:L$18) -> 0.06295092
A18: TOTIS | B18: 106223.09 | C18: 124286.53 | D18: 121987.56 | G18: 311692.93 | H18: 0 | I18: 7272.0841 | J18: 837255.99 | L18: =SUM(B18:J18) -> 1508718.2 | M18: =L18/SUM(L$2:L$18) -> 0.028341502
A19: TOTALES | B19: =SUM(B2:B18) -> 4781234.3 | C19: =SUM(C2:C18) -> 13381879 | D19: =SUM(D2:D18) -> 3836521.3 | E19: =SUM(E2:E18) -> 0 | G19: =SUM(G2:G18) -> 6455777.1 | H19: =SUM(H2:H18) -> 444352.52 | I19: =SUM(I2:I18) -> 123625.43 | J19: =SUM(J2:J18) -> 24210139 | L19: =SUM(L2:L18) -> 53233529 | M19: =SUM(M2:M18) -> 1
A22: Socio | B22: ADV 0202 | C22: ADV 0902 | D22: ADV 1702 | E22: ADV 2402 | F22: ADV | G22: NQN 1502 | H22: NQN 2402 | I22: NQN 2802 | J22: NQN 4 | K22: NQN 5 | L22: Totales
A23: ALVAREZ LUCAS | B23: 354427.22 | C23: 320582.1 | D23: 825847.09 | E23: 112788.54 | G23: 483150.42 | H23: 18138.262 | I23: 952332.8 | L23: =SUM(B23:J23) -> 3067266.4 | M23: =L23/SUM(L$23:L$39) -> 0.057591411
A24: BURGUEÑO LUCAS | B24: 468479.51 | C24: 320562.06 | D24: 825797.27 | E24: 112738.72 | G24: 491119.39 | H24: 18138.262 | I24: 952332.8 | L24: =SUM(B24:J24) -> 3189168 | M24: =L24/SUM(L$23:L$39) -> 0.059880251
A25: CONSIGLI ROBERTO CARLOS | B25: 468445.89 | C25: 320540.76 | D25: 825744.29 | E25: 112685.74 | G25: 507544.33 | H25: 18138.262 | I25: 952332.8 | L25: =SUM(B25:J25) -> 3205432.1 | M25: =L25/SUM(L$23:L$39) -> 0.060185628
A26: ESPINOSA | B26: 215000.56 | C26: 87494.229 | D26: 830734.26 | E26: 113413.83 | G26: 479660.72 | H26: 18138.262 | I26: 944926.42 | L26: =SUM(B26:J26) -> 2689368.3 | M26: =L26/SUM(L$23:L$39) -> 0.050495944
A27: GARCIA | B27: 468445.89 | C27: 320540.76 | D27: 825744.29 | E27: 112685.74 | G27: 507544.33 | H27: 18138.262 | I27: 952332.8 | L27: =SUM(B27:J27) -> 3205432.1 | M27: =L27/SUM(L$23:L$39) -> 0.060185628
A28: GIOJA MARIO ERNESTO | B28: 468445.89 | C28: 320540.76 | D28: 825744.29 | E28: 112685.74 | G28: 507544.33 | H28: 18138.262 | I28: 952332.8 | L28: =SUM(B28:J28) -> 3205432.1 | M28: =L28/SUM(L$23:L$39) -> 0.060185628
A29: GOGORZA NICOLAS | B29: 468445.89 | C29: 320540.76 | D29: 825744.29 | E29: 112685.74 | G29: 507544.33 | H29: 18138.262 | I29: 952332.8 | L29: =SUM(B29:J29) -> 3205432.1 | M29: =L29/SUM(L$23:L$39) -> 0.060185628
A30: GRANDE NADIA | B30: 468445.89 | C30: 320540.76 | D30: 825744.29 | E30: 112685.74 | G30: 507544.33 | H30: 18138.262 | I30: 952332.8 | L30: =SUM(B30:J30) -> 3205432.1 | M30: =L30/SUM(L$23:L$39) -> 0.060185628
A31: GUDIÑO GABRIELA | B31: 468445.89 | C31: 320540.76 | D31: 825744.29 | E31: 112685.74 | G31: 507544.33 | H31: 18138.262 | I31: 952332.8 | L31: =SUM(B31:J31) -> 3205432.1 | M31: =L31/SUM(L$23:L$39) -> 0.060185628
A32: HARRIAGUE LUCIA | B32: 468445.89 | C32: 320540.76 | D32: 825744.29 | E32: 112685.74 | G32: 507544.33 | H32: 18138.262 | I32: 952332.8 | L32: =SUM(B32:J32) -> 3205432.1 | M32: =L32/SUM(L$23:L$39) -> 0.060185628
A33: MACIAS | B33: 468445.89 | C33: 320540.76 | D33: 825744.29 | E33: 112685.74 | G33: 507544.33 | H33: 18138.262 | I33: 952332.8 | L33: =SUM(B33:J33) -> 3205432.1 | M33: =L33/SUM(L$23:L$39) -> 0.060185628
A34: MELO MAURO | B34: 468445.89 | C34: 320540.76 | D34: 825744.29 | E34: 112685.74 | G34: 507544.33 | H34: 18138.262 | I34: 952332.8 | L34: =SUM(B34:J34) -> 3205432.1 | M34: =L34/SUM(L$23:L$39) -> 0.060185628
... A39: TOTIS | B39: 215000.56 | C39: 87494.229 | D39: 830734.26 | E39: 113413.83 | G39: 479660.72 | H39: 18138.262 | I39: 944926.42 | L39: =SUM(B39:J39) -> 2689368.3 | M39: =L39/SUM(L$23:L$39) -> 0.050495944
A40: TOTALES | B40: =SUM(B23:B39) -> 7320158.1 | C40: =SUM(C23:C39) -> 4983203.9 | D40: =SUM(D23:D39) -> 14047892 | E40: =SUM(E23:E39) -> 1917372.6 | G40: =SUM(G23:G39) -> 8507273.7 | H40: =SUM(H23:H39) -> 308350.45 | I40: =SUM(I23:I39) -> 16174845 | J40: =SUM(J23:J39) -> 0 | L40: =SUM(L23:L39) -> 53259095 | M40: =SUM(M23:M39) -> 1
A43: Socio | B43: ADV 0303 | C43: ADV 1003 | D43: RN 1003 | E43: ADV 1703 | F43: ADV 2403 | G43: ADV 3103 | H43: NQN 1503 | I43: NQN 3101 | J43: NQN 2802 | K43: NQN 4 | L43: NQN 5 | M43: Totales
A44: ALVAREZ LUCAS | B44: 401264.26 | C44: 163866.95 | D44: 0 | E44: 841924.57 | F44: 161803 | G44: 229877.03 | H44: 1243174.4 | I44: 998033.17 | M44: =SUM(B44:K44) -> 4039943.3 | N44: =M44/SUM(M$44:M$60) -> 0.059872206
A45: BURGUEÑO LUCAS | B45: 401213.83 | C45: 166762.77 | D45: 13514.669 | E45: 841260.3 | F45: 161803 | G45: 228136.51 | H45: 1243174.4 | I45: 1002460.7 | M45: =SUM(B45:K45) -> 4058326.1 | N45: =M45/SUM(M$44:M$60) -> 0.060144641
A46: CONSIGLI ROBERTO CARLOS | B46: 401160.22 | C46: 166585.96 | D46: 13514.669 | E46: 841171.67 | F46: 161803 | G46: 228136.51 | H46: 1243174.4 | I46: 1002460.7 | M46: =SUM(B46:K46) -> 4058007.1 | N46: =M46/SUM(M$44:M$60) -> 0.060139912
A47: ESPINOSA | B47: 388762.89 | C47: 167538.14 | D47: 0 | E47: 754825.74 | F47: 148328.91 | G47: 131909.06 | H47: 730456.05 | I47: 996375.61 | M47: =SUM(B47:K47) -> 3318196.4 | N47: =M47/SUM(M$44:M$60) -> 0.049175873
A48: GARCIA | B48: 401160.22 | C48: 166585.96 | D48: 13514.669 | E48: 841171.67 | F48: 161803 | G48: 228136.51 | H48: 1243174.4 | I48: 1002460.7 | M48: =SUM(B48:K48) -> 4058007.1 | N48: =M48/SUM(M$44:M$60) -> 0.060139912
...

Sheet 2022
B1: RN 0701 | C1: RN 1401 | D1: NQN 1501 | E1: RN 2001 | F1: RN 2801 | G1: NQN 3101
A2: ALVAREZ LUCAS | H2: =SUM(B2:G2) -> 0 | I2: =H2/SUM(H$2:H$16) -> 0 | K2: INGRESO | L2: MATIAS | M2: LUCAS | N2: JP
A3: BURGUEÑO LUCAS | B3: 52157.77 | C3: 60921.17 | D3: 246971.41 | E3: 33756.43 | F3: 99289.09 | G3: 411115.01 | H3: =SUM(B3:G3) -> 904210.88 | I3: =H3/SUM(H$2:H$16) -> 0.036703573 | K3: ENERO | L3: =I15 -> 0 | M3: 0 | N3: =I16 -> 0.080274703
A4: CONSIGLI ROBERTO CARLOS | B4: 170257.36 | C4: 213470.71 | D4: 581825.82 | E4: 522478.42 | F4: 103529.43 | G4: 386045.02 | H4: =SUM(B4:G4) -> 1977606.8 | I4: =H4/SUM(H$2:H$16) -> 0.080274675 | K4: FEBRERO | L4: =I35 -> 0.0036335562 | M4: 0 | N4: =I36 -> 0.078517063
A5: GARCIA | B5: 170257.36 | C5: 213470.71 | D5: 581826.51 | E5: 522478.42 | F5: 103529.43 | G5: 386045.03 | H5: =SUM(B5:G5) -> 1977607.5 | I5: =H5/SUM(H$2:H$16) -> 0.080274704 | K5: MARZO | L5: =K55 -> 0.013132126 | M5: 0 | N5: =K56 -> 0.076568229
A6: GIOJA MARIO ERNESTO | B6: 170257.36 | C6: 213470.71 | D6: 581826.31 | E6: 522478.42 | F6: 103529.43 | G6: 386045.04 | H6: =SUM(B6:G6) -> 1977607.3 | I6: =H6/SUM(H$2:H$16) -> 0.080274696 | K6: ABRIL | L6: =M74 -> 0.027281224 | M6: 0.0029251956 | N6: =M75 -> 0.074627899
A7: GOGORZA NICOLAS | B7: 170257.36 | C7: 213470.71 | D7: 581826.44 | E7: 522478.42 | F7: 103529.43 | G7: 386044.77 | H7: =SUM(B7:G7) -> 1977607.1 | I7: =H7/SUM(H$2:H$16) -> 0.08027469 | K7: MAYO | L7: =N92 -> 0.046304126 | M7: 0.01505265 | N7: =N93 -> 0.072497687
A8: GRANDE NADIA | B8: 170257.36 | C8: 213470.71 | D8: 581826.17 | E8: 522478.42 | F8: 103529.43 | G8: 386045.06 | H8: =SUM(B8:G8) -> 1977607.1 | I8: =H8/SUM(H$2:H$16) -> 0.080274691 | K8: JUNIO | L8: =O111 -> 0.057185704 | M8: 0.037436039 | N8: =O112 -> 0.069856696
A9: GUDIÑO GABRIELA | B9: 170257.36 | C9: 213470.71 | D9: 581826.31 | E9: 522478.42 | F9: 103529.43 | G9: 386045.07 | H9: =SUM(B9:G9) -> 1977607.3 | I9: =H9/SUM(H$2:H$16) -> 0.080274697 | K9: JULIO | L9: =N130 -> 0.061356163 | M9: 0.048561853 | N9: =N131 -> 0.068543883
A10: HARRIAGUE LUCIA | B10: 170257.36 | C10: 213470.71 | D10: 581826.79 | E10: 522478.42 | F10: 103529.43 | G10: 386045.08 | H10: =SUM(B10:G10) -> 1977607.8 | I10: =H10/SUM(H$2:H$16) -> 0.080274717 | K10: AGOSTO | L10: =L149 -> 0.066691335 | M10: 0.06042397 | N10: =L150 -> 0.067155722
A11: MACIAS | B11: 170257.36 | C11: 213470.71 | D11: 581826.85 | E11: 522478.42 | F11: 103529.43 | G11: 386045.09 | H11: =SUM(B11:G11) -> 1977607.9 | I11: =H11/SUM(H$2:H$16) -> 0.08027472 | K11: SEPTIEMBRE | L11: =L168 -> 0.065226402 | M11: 0.065191677 | N11: =L169 -> 0.066890675
A12: MELO MAURO | B12: 170257.36 | C12: 213470.71 | D12: 581826.48 | E12: 522478.42 | F12: 103529.43 | G12: 386045.1 | H12: =SUM(B12:G12) -> 1977607.5 | I12: =H12/SUM(H$2:H$16) -> 0.080274705 | K12: OCTUBRE | L12: =K187 -> 0.063011645 | M12: 0.062946018 | N12: =K188 -> 0.067243403
A13: QUIROGA MARTIN | B13: 170257.36 | C13: 213470.71 | D13: 581826.82 | E13: 522478.42 | F13: 103529.43 | G13: 386045.11 | H13: =SUM(B13:G13) -> 1977607.9 | I13: =H13/SUM(H$2:H$16) -> 0.08027472
A14: SAN MARTIN | B14: 170257.36 | C14: 213470.71 | D14: 581826.53 | E14: 522478.42 | F14: 103529.43 | G14: 386045.12 | H14: =SUM(B14:G14) -> 1977607.6 | I14: =H14/SUM(H$2:H$16) -> 0.080274708
A15: SCHVARTZMAN MATIAS | I15: =H15/SUM(H$2:H$16) -> 0
A16: SERRANO GAMARRA JUAN | B16: 170257.36 | C16: 213470.71 | D16: 581826.4 | E16: 522478.42 | F16: 103529.43 | G16: 386045.13 | H16: =SUM(B16:G16) -> 1977607.4 | I16: =H16/SUM(H$2:H$16) -> 0.080274703
H17: =SUM(H2:H16) -> 24635500 | I17: =SUM(I2:I16) -> 1
B21: RN 0402 | C21: RN 1102 | D21: NQN 1502 | E21: RN 2502 | F21: NQN 2502 | G21: AV 2502
A22: ALVAREZ LUCAS | F22: 0.01 | G22: 0 | H22: =SUM(B22:G22) -> 0.01 | I22: =H22/SUM(H$22:H$36) -> 4.4058224e-10
A23: BURGUEÑO LUCAS | B23: 228320.34 | C23: 72126.53 | D23: 372056.19 | E23: 197548.83 | F23: 337771.69 | G23: 21500.39 | H23: =SUM(B23:G23) -> 1229324 | I23: =H23/SUM(H$22:H$36) -> 0.054161831
A24: CONSIGLI ROBERTO CARLOS | B24: 229886.43 | C24: 203320.68 | D24: 704073.6 | E24: 306854.21 | F24: 319208.7 | G24: 18776.02 | H24: =SUM(B24:G24) -> 1782119.6 | I24: =H24/SUM(H$22:H$36) -> 0.078517026
A25: GARCIA | B25: 229886.43 | C25: 203320.68 | D25: 704073.72 | E25: 306854.21 | F25: 319209.04 | G25: 18776.02 | H25: =SUM(B25:G25) -> 1782120.1 | I25: =H25/SUM(H$22:H$36) -> 0.078517047
A26: GIOJA MARIO ERNESTO | B26: 229886.43 | C26: 203320.68 | D26: 704074.04 | E26: 306854.21 | F26: 319209.05 | G26: 18776.01 | H26: =SUM(B26:G26) -> 1782120.4 | I26: =H26/SUM(H$22:H$36) -> 0.078517061
A27: GOGORZA NICOLAS | B27: 229886.43 | C27: 203320.68 | D27: 704073.95 | E27: 306854.21 | F27: 319208.73 | G27: 18776.02 | H27: =SUM(B27:G27) -> 1782120 | I27: =H27/SUM(H$22:H$36) -> 0.078517043
A28: GRANDE NADIA | B28: 229886.43 | C28: 203320.68 | D28: 704074.09 | E28: 306854.21 | F28: 319208.74 | G28: 18776.02 | H28: =SUM(B28:G28) -> 1782120.2 | I28: =H28/SUM(H$22:H$36) -> 0.07851705
A29: GUDIÑO GABRIELA | B29: 229886.43 | C29: 203320.68 | D29: 704073.59 | E29: 306854.21 | F29: 319208.75 | G29: 18776.02 | H29: =SUM(B29:G29) -> 1782119.7 | I29: =H29/SUM(H$22:H$36) -> 0.078517028
A30: HARRIAGUE LUCIA | B30: 229886.43 | C30: 203320.68 | D30: 704073.71 | E30: 306854.21 | F30: 319208.76 | G30: 18776.02 | H30: =SUM(B30:G30) -> 1782119.8 | I30: =H30/SUM(H$22:H$36) -> 0.078517034
A31: MACIAS | B31: 229886.43 | C31: 203320.68 | D31: 704074.23 | E31: 306854.21 | F31: 319209.1 | G31: 18776.01 | H31: =SUM(B31:G31) -> 1782120.7 | I31: =H31/SUM(H$22:H$36) -> 0.078517071
A32: MELO MAURO | B32: 229886.43 | C32: 203320.68 | D32: 704074.18 | E32: 306854.21 | F32: 319208.78 | G32: 18776.01 | H32: =SUM(B32:G32) -> 1782120.3 | I32: =H32/SUM(H$22:H$36) -> 0.078517055
A33: QUIROGA MARTIN | B33: 229886.43 | C33: 203320.68 | D33: 704074.29 | E33: 306854.21 | F33: 319208.79 | G33: 18776.01 | H33: =SUM(B33:G33) -> 1782120.4 | I33: =H33/SUM(H$22:H$36) -> 0.07851706
A34: SAN MARTIN | B34: 229886.43 | C34: 203320.68 | D34: 704074.26 | E34: 306854.21 | F34: 319209.13 | G34: 18776.01 | H34: =SUM(B34:G34) -> 1782120.7 | I34: =H34/SUM(H$22:H$36) -> 0.078517074
A35: SCHVARTZMAN MATIAS | F35: 82878.14 | G35: -406.45 | H35: =SUM(B35:G35) -> 82471.69 | I35: =H35/SUM(H$22:H$36) -> 0.0036335562
A36: SERRANO GAMARRA JUAN | B36: 229886.43 | C36: 203320.68 | D36: 704074.32 | E36: 306854.21 | F36: 319208.82 | G36: 18776.01 | H36: =SUM(B36:G36) -> 1782120.5 | I36: =H36/SUM(H$22:H$36) -> 0.078517063
H37: =SUM(H22:H36) -> 22697238 | I37: =SUM(I22:I36) -> 1
B41: RN 1103 | C41: RN 1803 | D41: ADV 1103 | E41: ADV 1803 | F41: ADV 2503 | G41: RN 2503 | H41: NQN 1603 | I41: NQN 3103 | L41: Transferencia sociedad
A42: ALVAREZ LUCAS | B42: 0 | C42: 0 | D42: 0 | E42: 0 | F42: 0 | H42: 0 | I42: 0.01 | J42: =SUM(B42:I42) -> 0.01 | K42: =J42/SUM(J$42:J$56) -> 3.5234456e-10 | L42: =D42+E42+F42+C61+G22 -> 0
A43: BURGUEÑO LUCAS | B43: 636644.59 | C43: 0 | D43: 82772.84 | E43: 70777.018 | F43: 66351.88 | G43: 334732.06 | H43: 398138.74 | I43: 341912.69 | J43: =SUM(B43:I43) -> 1931329.8 | K43: =J43/SUM(J$42:J$56) -> 0.068049355 | L43: =D43+E43+F43+C62+G23 -> 339833.9
A44: CONSIGLI ROBERTO CARLOS | B44: 636644.59 | C44: 40573.32 | D44: 82772.84 | E44: 70777.018 | F44: 66224.59 | G44: 334732.06 | H44: 526373.55 | I44: 415007.7 | J44: =SUM(B44:I44) -> 2173105.7 | K44: =J44/SUM(J$42:J$56) -> 0.076568196 | L44: =D44+E44+F44+C63+G24 -> 335571.84
A45: GARCIA | B45: 636644.59 | C45: 40573.32 | D45: 82772.84 | E45: 70777.018 | F45: 66224.59 | G45: 334732.06 | H45: 526374.11 | I45: 415008.04 | J45: =SUM(B45:I45) -> 2173106.6 | K45: =J45/SUM(J$42:J$56) -> 0.076568228 | L45: =D45+E45+F45+C64+G25 -> 335571.84
A46: GIOJA MARIO ERNESTO | B46: 636644.59 | C46: 40573.32 | D46: 82772.84 | E46: 70777.018 | F46: 66224.59 | G46: 334732.06 | H46: 526373.37 | I46: 415008.05 | J46: =SUM(B46:I46) -> 2173105.8 | K46: =J46/SUM(J$42:J$56) -> 0.076568202 | L46: =D46+E46+F46+C65+G26 -> 335571.83
...

Sheet 2020
B1: RN 0301 | C1: NQN 0301 | D1: RN 1001 | E1: NQN 1001 | F1: RN 1701 | G1: NQN 1701 | H1: RN 2401 | I1: NQN 2401 | J1: RN 3101
A2: Consigli | B2: 88016.657 | C2: 44935.01 | D2: 123823.44 | E2: 74540.26 | F2: 107649.96 | G2: 109002.71 | H2: 282439.49 | I2: 164205.95 | J2: 118243.91 | K2: 1112857.4 | L2: 0.0988 | N2: 92720807
A3: Etulain | B3: 88016.657 | C3: 44935.02 | D3: 123823.44 | E3: 74540.15 | F3: 107649.96 | G3: 109003.02 | H3: 282439.49 | I3: 165564.02 | J3: 118243.91 | K3: 1114215.7 | L3: 0.0989
A4: García | B4: 87880.209 | C4: 40448.03 | D4: 123823.44 | E4: 71337.03 | F4: 107649.96 | G4: 108240.03 | H4: 282439.49 | I4: 61819.03 | J4: 118243.91 | K4: 1001881.1 | L4: 0.0889
A5: Gioja | B5: 88016.657 | C5: 44935.04 | D5: 123823.44 | E5: 74540.33 | F5: 107649.96 | G5: 109003.04 | H5: 282439.49 | I5: 164205.98 | J5: 118243.91 | K5: 1112857.8 | L5: 0.0988
A6: Gogorza | B6: 88016.657 | C6: 44935.05 | D6: 123823.44 | E6: 74539.94 | F6: 107649.96 | G6: 109003.05 | H6: 282439.49 | I6: 164205.99 | J6: 118243.91 | K6: 1112857.5 | L6: 0.0988
A7: Grande | B7: 52989.317 | C7: 26961.06 | D7: 74546.766 | E7: 45518.78 | F7: 64809.67 | G7: 65402.06 | H7: 170040.1 | I7: 107536 | J7: 71187.659 | K7: 678991.41 | L7: 0.0603
A8: Gudiño | B8: 88016.657 | C8: 44935.07 | D8: 123823.44 | E8: 74539.89 | F8: 107649.96 | G8: 109002.82 | H8: 282439.49 | I8: 164206.01 | J8: 118243.91 | K8: 1112857.2 | L8: 0.0988
A9: Harriague | B9: 88016.657 | C9: 44935.08 | D9: 123823.44 | E9: 74539.77 | F9: 107649.96 | G9: 109003.08 | H9: 282439.49 | I9: 164206.02 | J9: 118243.91 | K9: 1112857.4 | L9: 0.0988
A10: Melo | B10: 88016.657 | C10: 44935.09 | D10: 123823.44 | E10: 74540.07 | F10: 107649.96 | G10: 109003.09 | H10: 282439.49 | I10: 164206.03 | J10: 118243.91 | K10: 1112857.7 | L10: 0.0988
A11: Quiroga | B11: 88016.657 | C11: 44935.1 | D11: 123823.44 | E11: 74539.79 | F11: 107649.96 | G11: 109003.1 | H11: 282439.49 | I11: 164206.04 | J11: 118243.91 | K11: 1112857.5 | L11: 0.0988
A12: Serrano | B12: 52989.317 | C12: 26961.11 | D12: 74546.766 | E12: 45518.71 | F12: 64809.67 | G12: 65402.11 | H12: 170040.1 | I12: 107026.05 | J12: 71187.659 | K12: 678481.49 | L12: 0.0602
A13: Materiales | C13: 23887.04 | E13: 23943.9 | G13: 57204.06 | I13: 83391.13 | K13: 188426.12
L14: 11451998
B15: RN 0702 | C15: NQN 0702 | D15: RN 1402 | E15: NQN 1402 | F15: RN 2102 | G15: NQN 2102
A16: Consigli | B16: 81208.36 | C16: 284965.11 | D16: 204183.1 | E16: 63725.01 | F16: 124233.17 | G16: 178075.01 | H16: 936389.76 | I16: 0.0987
A17: Etulain | B17: 81208.36 | C17: 284935.02 | D17: 204183.1 | E17: 63715.02 | F17: 124233.17 | G17: 177085.02 | H17: 935359.69 | I17: 0.0986
A18: García | B18: 81208.36 | C18: 114823.03 | D18: 204183.1 | E18: 64579.03 | F18: 124233.17 | G18: 168582.03 | H18: 757608.72 | I18: 0.0799
A19: Gioja | B19: 81208.36 | C19: 284964.84 | D19: 204183.1 | E19: 63725.26 | F19: 124233.17 | G19: 178075.46 | H19: 936390.19 | I19: 0.0987
A20: Gogorza | B20: 81208.36 | C20: 284965.09 | D20: 204183.1 | E20: 63725.05 | F20: 124233.17 | G20: 178075.05 | H20: 936389.82 | I20: 0.0987
A21: Grande | B21: 48890.75 | C21: 179831.93 | D21: 168521.73 | E21: 38149.06 | F21: 75510.37 | G21: 107861.06 | H21: 618764.9 | I21: 0.0652
A22: Gudiño | B22: 81208.36 | C22: 284965.03 | D22: 204183.1 | E22: 63725.83 | F22: 124233.17 | G22: 178075.07 | H22: 936390.56 | I22: 0.0987
A23: Harriague | B23: 81208.36 | C23: 284964.92 | D23: 204183.1 | E23: 63725.08 | F23: 124233.17 | G23: 178075.08 | H23: 936389.71 | I23: 0.0987
A24: Melo | B24: 81208.36 | C24: 284965.22 | D24: 204183.1 | E24: 63725.09 | F24: 124233.17 | G24: 178075.09 | H24: 936390.03 | I24: 0.0987
A25: Quiroga | B25: 81208.36 | C25: 284964.94 | D25: 204183.1 | E25: 63725.1 | F25: 124233.17 | G25: 178075.1 | H25: 936389.77 | I25: 0.0987
A26: Serrano | B26: 48890.75 | C26: 179843.1 | D26: 168521.73 | E26: 38152.11 | F26: 75510.37 | G26: 107861.11 | H26: 618779.17 | I26: 0.0652
A27: Materiales | C27: 130401.24 | E27: 33704.61 | G27: 94697.34 | H27: 258803.19
J28: 9744045.5
B30: RN 0603 | C30: NQN 0603 | D30: RN 1303 | E30: NQN 1303 | F30: RN 2003 | G30: NQN 2003 | H30: RN 2703 | I30: NQN 2703
A31: Consigli | B31: 135754.98 | C31: 88667.92 | D31: 253142.4 | E31: 61396.28 | F31: 84852.401 | G31: 141119.95 | H31: 151706.43 | I31: 55806.01 | J31: 972446.37 | K31: 0.0978
A32: Etulain | B32: 135754.98 | C32: 88732.15 | D32: 253142.4 | E32: 61392.02 | F32: 84852.401 | G32: 141120.02 | H32: 151706.43 | I32: 55778.02 | J32: 972478.42 | K32: 0.0978
A33: García | B33: 135754.98 | C33: 93245.03 | D33: 253102.05 | E33: 61748.03 | F33: 84852.401 | G33: 132193.03 | H33: 151702.28 | I33: 57448.03 | J33: 970045.83 | K33: 0.0975
A34: Gioja | B34: 135754.98 | C34: 88667.85 | D34: 253142.4 | E34: 61396.04 | F34: 84852.401 | G34: 141119.98 | H34: 151706.43 | I34: 55806.04 | J34: 972446.12 | K34: 0.0978
A35: Gogorza | B35: 135754.98 | C35: 88667.24 | D35: 253142.4 | E35: 61396.25 | F35: 84852.401 | G35: 141119.99 | H35: 151706.43 | I35: 55806.05 | J35: 972445.74 | K35: 0.0978
A36: Grande | B36: 81730.04 | C36: 51415.25 | D36: 160862.77 | E36: 36802.09 | F36: 53666.622 | G36: 86207 | H36: 93700 | I36: 33847.06 | J36: 598230.83 | K36: 0.0601
A37: Gudiño | B37: 135754.98 | C37: 88667.26 | D37: 253142.4 | E37: 61396.66 | F37: 84852.401 | G37: 141120.05 | H37: 151706.43 | I37: 55806.32 | J37: 972446.5 | K37: 0.0978
A38: Harriague | B38: 135754.98 | C38: 88667.27 | D38: 253142.4 | E38: 61397.08 | F38: 84852.401 | G38: 141120.02 | H38: 151706.43 | I38: 55806.08 | J38: 972446.66 | K38: 0.0978
A39: Melo | B39: 135754.98 | C39: 88667.28 | D39: 253142.4 | E39: 61396.38 | F39: 84852.401 | G39: 141120.03 | H39: 151706.43 | I39: 55806.09 | J39: 972445.99 | K39: 0.0978
A40: Quiroga | B40: 135754.98 | C40: 88667.29 | D40: 253142.4 | E40: 61397.1 | F40: 84852.401 | G40: 141120.04 | H40: 151706.43 | I40: 55806.1 | J40: 972446.74 | K40: 0.0978
A41: Serrano | B41: 81730.04 | C41: 51414.3 | D41: 160862.77 | E41: 36804.11 | F41: 53666.622 | G41: 86207.05 | H41: 93700 | I41: 33857.11 | J41: 598242 | K41: 0.0601
...

Sheet 2019
B1: NQN 2901 | C1: NQN 1701 | D1: RN 3001 | E1: RN 1701 | I1: Promedio ingresos | J1: Porcentajes | N1: Promedio en porcentajes 3 ultimos meses 1 full mas (con el ingreso de los dos como full) | T1: Promedio en porcentajes 3 ultimos meses todos como full
A2: Consigli | B2: 14178.01 | C2: 238694.01 | D2: 103958.01 | E2: 317338.25 | F2: 674168.28 | G2: 0.1144 | I2: Consigli | J2: 0.098 | K2: 937413.73 | N2: Consigli | O2: 0.0893 | P2: 853716.07 | Q2: 83697.65 | T2: Consigli | U2: 0.0833 | V2: 796801.67 | W2: 140612.06
A3: Etulain | B3: -29.98 | C3: -10.98 | D3: 0 | E3: 0 | F3: -40.96 | G3: 0 | I3: Etulain | J3: 0.098 | K3: 937413.73 | N3: Alan | O3: 0.0893 | P3: 853716.07 | Q3: 83697.65 | T3: Alan | U3: 0.0833 | V3: 796801.67 | W3: 140612.06
A4: Gioja | B4: 14178.03 | C4: 238694.03 | D4: 103958.01 | E4: 317338.25 | F4: 674168.32 | G4: 0.1144 | I4: Gioja | J4: 0.098 | K4: 937413.73 | N4: Gioja | O4: 0.0893 | P4: 853716.07 | Q4: 83697.65 | T4: Gioja | U4: 0.0833 | V4: 796801.67 | W4: 140612.06
A5: Gogorza | B5: 14178.04 | C5: 238694.04 | D5: 103958.01 | E5: 317338.25 | F5: 674168.34 | G5: 0.1144 | I5: Gogorza | J5: 0.098 | K5: 937413.73 | N5: Gogorza | O5: 0.0893 | P5: 853716.07 | Q5: 83697.65 | T5: Gogorza | U5: 0.0833 | V5: 796801.67 | W5: 140612.06
A6: Grande | B6: 10049.05 | C6: 161627.05 | D6: 62375.92 | E6: 190392.33 | F6: 424444.35 | G6: 0.072 | I6: Grande | J6: 0.0588 | K6: 562448.24 | N6: Grande | O6: 0.0536 | P6: 512229.64 | Q6: 50218.59 | T6: Grande | U6: 0.0833 | V6: 796801.67 | W6: -234353.43
A7: Gudiño | B7: 14178.06 | C7: 238694.06 | D7: 103958.01 | E7: 317338.25 | F7: 674168.38 | G7: 0.1144 | I7: Gudiño | J7: 0.098 | K7: 937413.73 | N7: Gudiño | O7: 0.0893 | P7: 853716.07 | Q7: 83697.65 | T7: Gudiño | U7: 0.0833 | V7: 796801.67 | W7: 140612.06
A8: Harriague | B8: 14178.07 | C8: 238694.07 | D8: 103958.01 | E8: 317338.25 | F8: 674168.4 | G8: 0.1144 | I8: Harriague | J8: 0.098 | K8: 937413.73 | N8: Harriague | O8: 0.0893 | P8: 853716.07 | Q8: 83697.65 | T8: Harriague | U8: 0.0833 | V8: 796801.67 | W8: 140612.06
A9: Melo | B9: 14178.08 | C9: 238694.08 | D9: 103958.01 | E9: 317338.25 | F9: 674168.42 | G9: 0.1144 | I9: Melo | J9: 0.098 | K9: 937413.73 | N9: Melo | O9: 0.0893 | P9: 853716.07 | Q9: 83697.65 | T9: Melo | U9: 0.0833 | V9: 796801.67 | W9: 140612.06
A10: Moscuzza | B10: 4591.09 | C10: 90950.09 | D10: 57405.01 | E10: 77865.02 | F10: 230811.21 | G10: 0.0392 | I10: Quiroga | J10: 0.098 | K10: 937413.73 | N10: Quiroga | O10: 0.0893 | P10: 853716.07 | Q10: 83697.65 | T10: Quiroga | U10: 0.0833 | V10: 796801.67 | W10: 140612.06
A11: Quiroga | B11: 14178.1 | C11: 238694.1 | D11: 103958.01 | E11: 317338.25 | F11: 674168.46 | G11: 0.1144 | I11: Serrano | J11: 0.0588 | K11: 562448.24 | N11: Serrano | O11: 0.0536 | P11: 512229.64 | Q11: 50218.59 | T11: Serrano | U11: 0.0833 | V11: 796801.67 | W11: -234353.43
A12: Serrano | B12: 11133.11 | C12: 178071.11 | D12: 65690.81 | E12: 265432.04 | F12: 520327.07 | G12: 0.0883 | I12: Garcia | J12: 0.098 | K12: 937413.73 | N12: Garcia | O12: 0.0893 | P12: 853716.07 | Q12: 83697.65 | T12: Garcia | U12: 0.0833 | V12: 796801.67 | W12: 140612.06
